
`
0custom_exceptions/employee_could_not_be_found.py,6\9\6983d656dfd85a01d13953b14af64d3e4cb05be0
G
e2etests/environment.py,0\9\09dcc01444e8d02398efa54a3373e19df788b48a
V
&util/database_generator_for_testing.py,9\d\9dddd1ceae5c96269d0cfcab3f1729810d95ecdd
r
Btests_for_app/test_for_data_access_layer/test_reimbursement_dao.py,d\2\d2f16bf3d866c5dd3cb5638988c92a6d74c963cd
q
Adata_access_layer/implementation_classes/reimbursement_dao_imp.py,e\1\e1678c43b4fb7355ba45c424f8964b3926ce34e5
H
tests_for_app/report.css,a\3\a3bc0d07033d444afdf8ec94bc29cbe3dfeb48e6
p
@data_access_layer/abstract_classes/reimbursement_dao_abstract.py,1\a\1a2b8d289429791823cdf7c2016c99b43e53c8df
;
records.log,c\f\cf429c79649736f8bdaec7f62f49f7cd74d8ccfc
Y
)tests_for_app/python_api_test_report.html,b\d\bd700cb4e4e5a956ca939c19d6418db116345f2b
@
requirements.txt,1\9\19359a61ae2446b51b549167b014da2fcf265768
K
util/database_connection.py,8\c\8c326ba587a4284574861a310da04caa55f66c66
:

.gitignore,a\5\a5cc2925ca8258af241be7e5b0381edf30266302
9
	README.md,8\e\8ec9a00bfd09b3190ac6b22251dbb1aa95a0579d
7
main.py,f\1\f1bdda93d9a278e358509d498e17d97764c1fb29
D
entities/employee.py,1\5\15057c7321d0ade21a1bac4f6ad483dab9c0d2eb
m
=tests_for_app/test_for_data_access_layer/test_employee_dao.py,c\3\c359961d69721c1f611c85e0c18a90c6d6beb658
c
3custom_exceptions/the_employee_id_is_not_numeric.py,0\2\02ba49207a68202a2e88577a9d97463141bc552d
a
1custom_exceptions/employee_information_invalid.py,0\5\05d17ea6c9d3832afe5249dc7d315419d08314ea
f
6custom_exceptions/that_reimbursement_is_not_pending.py,5\1\51889c3e1b0d4dc90617038a3dd2bfceda0cdd7a
l
<data_access_layer/implementation_classes/employee_dao_imp.py,d\8\d8e3392751c43637ab16dc1a569c2c556a00d5df