
`
0custom_exceptions/employee_could_not_be_found.py,6\9\6983d656dfd85a01d13953b14af64d3e4cb05be0
9
	README.md,8\e\8ec9a00bfd09b3190ac6b22251dbb1aa95a0579d
;
records.log,c\f\cf429c79649736f8bdaec7f62f49f7cd74d8ccfc
:

schema.sql,2\9\29b783fbfb399c04c04bfdf2e93fe4096efaae81
l
<service_layer/implementation_classes/employee_service_imp.py,4\0\407ca53147a5016dd5f8dc0d92ef636ebe4b6388
q
Aservice_layer/implementation_classes/reimbursement_service_imp.py,a\7\a749e89c0a47f7fe40ce7b73a8a436bbe8118de1
G
e2etests/environment.py,0\9\09dcc01444e8d02398efa54a3373e19df788b48a
K
util/database_connection.py,8\c\8c326ba587a4284574861a310da04caa55f66c66
l
<data_access_layer/implementation_classes/employee_dao_imp.py,d\8\d8e3392751c43637ab16dc1a569c2c556a00d5df
V
&util/database_generator_for_testing.py,9\d\9dddd1ceae5c96269d0cfcab3f1729810d95ecdd
m
=tests_for_app/test_for_data_access_layer/test_employee_dao.py,c\3\c359961d69721c1f611c85e0c18a90c6d6beb658
D
entities/employee.py,1\5\15057c7321d0ade21a1bac4f6ad483dab9c0d2eb